<?xml version="1.0"?>
<robot name="smarty">

  <material name="grey">
    <color rgba="0.2 0.2 0.2 0.7"/>
  </material>

  <material name="black">
    <color rgba="0 0 0 0.7"/>
  </material>

  <material name="yellow">
    <color rgba="1 1 0 0.7"/>
  </material>


  <link name="base_footprint">

    <inertial>
      <origin xyz="0 0 0"/>
      <mass value="1.0"/>
      <inertia ixx="0.0001" ixy="0.0" ixz="0.0" iyy="0.0001" iyz="0.0" izz="0.0001"/>
    </inertial>

    <visual>
      <geometry>
        <box size="0.001 0.001 0.001"/>
      </geometry>
      <origin xyz="0 0 0" rpy="0 0 0"/>
    </visual>


  </link>


  <link name="COM">

    <inertial>
      <origin xyz="0 0 0"/>
      <mass value="10"/>
      <inertia ixx="0.06667" ixy="0.0" ixz="0.0" iyy="7.533" iyz="0.0" izz="7.533"/>
    </inertial>

    <visual>
      <geometry>
        <box size="3 0.2 0.2"/>
      </geometry>
      <origin rpy="0 0 0" xyz="0 0 0"/>
      <material name="yellow"/>
    </visual>

    <collision>
      <geometry>
        <box size="3 0.2 0.2"/>
      </geometry>
      <origin rpy="0 0 0" xyz="0 0 0"/>
    </collision>

  </link>


  <joint name="joint1" type="fixed">
    <parent link="base_footprint"/>
    <child link="COM"/>
    <origin xyz="0 0 0.5" rpy="0 0 0"/>
  </joint>


  <link name="rear_wheel">

    <inertial>
      <origin xyz="0 0 0"/>
      <mass value="3.0"/>
      <inertia ixx="0.0525" ixy="0.0" ixz="0.0" iyy="0.0525" iyz="0.0" izz="0.06"/>
    </inertial>

    <visual>
      <geometry>
        <cylinder radius="0.2" length="0.2"/>
      </geometry>
      <origin xyz="0 0 0" rpy="1.57 0 0"/>
      <material name="black"/>
    </visual>

    <collision>
      <geometry>
        <cylinder radius="0.2" length="0.2"/>
      </geometry>
      <origin xyz="0 0 0" rpy="1.57 0 0"/>
    </collision>
  </link>


  <joint name="rear_wheel_joint" type="continuous">
    <parent link="COM"/>
    <child link="rear_wheel"/>
    <origin xyz="-1.2 0 -0.3" rpy="0 0 0"/>
    <axis xyz="0 1 0"/>
  </joint>


  <link name="front_wheel">

    <inertial>
      <origin xyz="0 0 0"/>
      <mass value="3.0"/>
      <inertia ixx="0.0525" ixy="0.0" ixz="0.0" iyy="0.0525" iyz="0.0" izz="0.06"/>
    </inertial>

    <visual>
      <geometry>
        <cylinder radius="0.2" length="0.2"/>
      </geometry>
      <origin xyz="0 0 0" rpy="1.57 0 0"/>
      <material name="black"/>
    </visual>

    <collision>
      <geometry>
        <cylinder radius="0.2" length="0.2"/>
      </geometry>
      <origin xyz="0 0 0" rpy="1.57 0 0"/>
    </collision>
  </link>


  <joint name="front_wheel_joint" type="revolute">
    <parent link="COM"/>
    <child link="front_wheel"/>
    <origin xyz="1.2 0 -0.3" rpy="0 0 0"/>
    <limit upper="0.8" lower="-0.8" effort="10" velocity="3"/>
    <axis xyz="0 0 1"/>
  </joint>

</robot>
